Workbook

Sheet 00_Leia-me
B2: EXECUTAR — HUB Control Plane
B4: Fonte primária de verdade (Release 1): esta planilha Google Sheets. O GitHub é espelho estrutural versionado (Release 2).
B6: COMO PREENCHER:
B7: 1. As abas 01_Formulario_<MACROAREA_ID> são a ÚNICA superfície de preenchimento humano.
B8: 2. A coluna 'Resposta' (fill amarelo-claro) é a ÚNICA célula editável em toda a planilha.
B9: 3. Todas as demais abas (02–09) são saídas derivadas — não editar diretamente.
B10: 4. As abas 10–24 (REG_*) são o registro normalizado — fonte estrutural, não editar diretamente.
B12: CONVENÇÃO DE COR:
B13: Preto + texto branco = cabeçalho de domínio (estrutura)
B14: Cinza claro = sub-cabeçalho de artefato
B15: Amarelo claro (fill) = input humano editável (só coluna Resposta)
B16: Azul (texto) = fórmula / referência viva a outra aba
... B22: Fontes: EXECUTAR_projetosaasentrypoint_EXPANDIDO.xlsx (referência de UX), EXECUTAR_CHECKLIST_D01-D23_GRANULAR.yaml, Progama_Master_index.docx, ecossistema_operacional.yaml

Sheet 01_Formulario_A00
F2: Progresso de preenchimento | G2: =COUNTA(D7:D328)&" / 307"
A4: A00 — Governança, Estratégia e Gestão
A5: ID | B5: Campo | C5: O que preencher | D5: Resposta | E5: Exemplo (referência)
A6: Domínio D0 — Pmbook Governança e Operação
A7: Domínio D01 — Gestão Empresarial
A8: Artefato D01-DOC-DDE-001 — Documento de Direção Empresarial
A9: D01-DOC-DDE-001.IDENTITY.NOME_DO_ECOSSISTEMA | B9: nome_do_ecossistema | C9: Definir, validar e manter: Nome Do Ecossistema | E9: alta
A10: D01-DOC-DDE-001.IDENTITY.DESCRICAO_EXECUTIVA | B10: descricao_executiva | C10: Definir, validar e manter: Descricao Executiva | E10: baixa
A11: D01-DOC-DDE-001.IDENTITY.CONTEXTO | B11: contexto | C11: Definir, validar e manter: Contexto | E11: baixa
A12: D01-DOC-DDE-001.IDENTITY.RAZAO_DE_EXISTENCIA | B12: razao_de_existencia | C12: Definir, validar e manter: Razao De Existencia | E12: baixa
A13: D01-DOC-DDE-001.IDENTITY.FASE_ATUAL | B13: fase_atual | C13: Definir, validar e manter: Fase Atual | E13: baixa
A14: D01-DOC-DDE-001.PROBLEM_AND_OPPORTUNITY.PROBLEMA_CENTRAL | B14: problema_central | C14: Definir, validar e manter: Problema Central | E14: baixa
A15: D01-DOC-DDE-001.PROBLEM_AND_OPPORTUNITY.PROBLEMAS_SECUNDARIOS | B15: problemas_secundarios | C15: Definir, validar e manter: Problemas Secundarios | E15: baixa
A16: D01-DOC-DDE-001.PROBLEM_AND_OPPORTUNITY.OPORTUNIDADE | B16: oportunidade | C16: Definir, validar e manter: Oportunidade | E16: baixa
A17: D01-DOC-DDE-001.PROBLEM_AND_OPPORTUNITY.EVIDENCIAS_DO_PROBLEMA | B17: evidencias_do_problema | C17: Definir, validar e manter: Evidencias Do Problema | E17: baixa
A18: D01-DOC-DDE-001.PURPOSE.PROPOSITO | B18: proposito | C18: Definir, validar e manter: Proposito | E18: baixa
A19: D01-DOC-DDE-001.PURPOSE.MISSAO | B19: missao | C19: Definir, validar e manter: Missao | E19: baixa
A20: D01-DOC-DDE-001.PURPOSE.VISAO | B20: visao | C20: Definir, validar e manter: Visao | E20: baixa
... A52: D01-DOC-DDE-001.DECISIONS.DECISOES_PENDENTES | B52: decisoes_pendentes | C52: Definir, validar e manter: Decisoes Pendentes | E52: baixa
A53: Artefato D01-DOC-TAP-001 — Termo de Abertura do Ecossistema
A54: D01-DOC-TAP-001.IDENTIFICATION.TITULO | B54: titulo | C54: Definir, validar e manter: Titulo | E54: baixa
A55: D01-DOC-TAP-001.IDENTIFICATION.JUSTIFICATIVA | B55: justificativa | C55: Definir, validar e manter: Justificativa | E55: baixa
A56: D01-DOC-TAP-001.IDENTIFICATION.CONTEXTO | B56: contexto | C56: Definir, validar e manter: Contexto | E56: baixa
A57: D01-DOC-TAP-001.IDENTIFICATION.SPONSOR | B57: sponsor | C57: Definir, validar e manter: Sponsor | E57: baixa
A58: D01-DOC-TAP-001.IDENTIFICATION.OWNER | B58: owner | C58: Definir, validar e manter: Owner | E58: baixa
A59: D01-DOC-TAP-001.OBJECTIVE.OBJETIVO_GERAL | B59: objetivo_geral | C59: Definir, validar e manter: Objetivo Geral | E59: baixa
A60: D01-DOC-TAP-001.OBJECTIVE.OBJETIVOS_ESPECIFICOS | B60: objetivos_especificos | C60: Definir, validar e manter: Objetivos Especificos | E60: baixa
A61: D01-DOC-TAP-001.OBJECTIVE.RESULTADO_FINAL_ESPERADO | B61: resultado_final_esperado | C61: Definir, validar e manter: Resultado Final Esperado | E61: baixa
A62: D01-DOC-TAP-001.SCOPE.ESCOPO_INCLUIDO | B62: escopo_incluido | C62: Definir, validar e manter: Escopo Incluido | E62: baixa
A63: D01-DOC-TAP-001.SCOPE.ESCOPO_EXCLUIDO | B63: escopo_excluido | C63: Definir, validar e manter: Escopo Excluido | E63: baixa
A64: D01-DOC-TAP-001.SCOPE.FRONTEIRAS | B64: fronteiras | C64: Definir, validar e manter: Fronteiras | E64: baixa
A65: D01-DOC-TAP-001.DELIVERABLES.ENTREGAVEIS_PRINCIPAIS | B65: entregaveis_principais | C65: Definir, validar e manter: Entregaveis Principais | E65: baixa
... A82: D01-DOC-TAP-001.APPROVALS.STATUS_APROVACAO | B82: status_aprovacao | C82: Definir, validar e manter: Status Aprovacao | E82: baixa
A83: Artefato D01-DOC-MNE-001 — Modelo de Negócio do Ecossistema
A84: D01-DOC-MNE-001.CUSTOMER.SEGMENTOS | B84: segmentos | C84: Definir, validar e manter: Segmentos | E84: baixa
A85: D01-DOC-MNE-001.CUSTOMER.USUARIOS | B85: usuarios | C85: Definir, validar e manter: Usuarios | E85: baixa
A86: D01-DOC-MNE-001.CUSTOMER.CLIENTES | B86: clientes | C86: Definir, validar e manter: Clientes | E86: baixa
A87: D01-DOC-MNE-001.CUSTOMER.PROBLEMAS | B87: problemas | C87: Definir, validar e manter: Problemas | E87: baixa
A88: D01-DOC-MNE-001.CUSTOMER.JTBD | B88: jtbd | C88: Definir, validar e manter: JTBD | E88: baixa
A89: D01-DOC-MNE-001.VALUE.PROPOSTAS_DE_VALOR | B89: propostas_de_valor | C89: Definir, validar e manter: Propostas De Valor | E89: baixa
...

Sheet 01_Formulario_A01
F2: Progresso de preenchimento | G2: =COUNTA(D7:D143)&" / 130"
A4: A01 — Negócio e Go-to-Market
A5: ID | B5: Campo | C5: O que preencher | D5: Resposta | E5: Exemplo (referência)
A6: Domínio D13 — Mercado e Geração de Demanda
A7: Artefato D13-DOC-DRM-001 — Documento de Requisitos de Mercado
A8: D13-DOC-DRM-001.MARKET.DEFINICAO | B8: definicao | C8: Definir, validar e manter: Definicao | E8: baixa
A9: D13-DOC-DRM-001.MARKET.TAMANHO | B9: tamanho | C9: Definir, validar e manter: Tamanho | E9: baixa
A10: D13-DOC-DRM-001.MARKET.TENDENCIA | B10: tendencia | C10: Definir, validar e manter: Tendencia | E10: baixa
A11: D13-DOC-DRM-001.SEGMENTS.SEGMENTO | B11: segmento | C11: Definir, validar e manter: Segmento | E11: baixa
A12: D13-DOC-DRM-001.SEGMENTS.NECESSIDADE | B12: necessidade | C12: Definir, validar e manter: Necessidade | E12: baixa
A13: D13-DOC-DRM-001.ICP.PERFIL | B13: perfil | C13: Definir, validar e manter: Perfil | E13: baixa
A14: D13-DOC-DRM-001.ICP.CRITERIOS | B14: criterios | C14: Definir, validar e manter: Criterios | E14: baixa
A15: D13-DOC-DRM-001.ICP.EXCLUSOES | B15: exclusoes | C15: Definir, validar e manter: Exclusoes | E15: baixa
A16: D13-DOC-DRM-001.DEMAND.SINAIS | B16: sinais | C16: Definir, validar e manter: Sinais | E16: baixa
A17: D13-DOC-DRM-001.DEMAND.PROBLEMAS | B17: problemas | C17: Definir, validar e manter: Problemas | E17: baixa
A18: D13-DOC-DRM-001.DEMAND.PROCURA | B18: procura | C18: Definir, validar e manter: Procura | E18: baixa
A19: D13-DOC-DRM-001.ALTERNATIVES.CONCORRENTES | B19: concorrentes | C19: Definir, validar e manter: Concorrentes | E19: baixa
... A34: D13-DOC-DRM-001.RISKS.RISCOS_DE_MERCADO | B34: riscos_de_mercado | C34: Definir, validar e manter: Riscos De Mercado | E34: baixa
A35: Artefato D13-DOC-GTM-001 — Plano de Entrada no Mercado e Lançamento
A36: D13-DOC-GTM-001.OBJECTIVES.OBJETIVO_DE_LANCAMENTO | B36: objetivo_de_lancamento | C36: Definir, validar e manter: Objetivo De Lancamento | E36: baixa
A37: D13-DOC-GTM-001.AUDIENCE.ICP | B37: icp | C37: Definir, validar e manter: Icp | E37: baixa
A38: D13-DOC-GTM-001.AUDIENCE.SEGMENTOS | B38: segmentos | C38: Definir, validar e manter: Segmentos | E38: baixa
A39: D13-DOC-GTM-001.POSITIONING.POSICIONAMENTO | B39: posicionamento | C39: Definir, validar e manter: Posicionamento | E39: baixa
A40: D13-DOC-GTM-001.POSITIONING.MENSAGEM | B40: mensagem | C40: Definir, validar e manter: Mensagem | E40: baixa
A41: D13-DOC-GTM-001.OFFER.PRODUTO | B41: produto | C41: Definir, validar e manter: Produto | E41: baixa
A42: D13-DOC-GTM-001.OFFER.PLANO | B42: plano | C42: Definir, validar e manter: Plano | E42: baixa
A43: D13-DOC-GTM-001.OFFER.PRECO | B43: preco | C43: Definir, validar e manter: Preco | E43: baixa
A44: D13-DOC-GTM-001.CHANNELS.CANAL | B44: canal | C44: Definir, validar e manter: Canal | E44: baixa
A45: D13-DOC-GTM-001.CHANNELS.FUNCAO | B45: funcao | C45: Definir, validar e manter: Funcao | E45: baixa
A46: D13-DOC-GTM-001.CONTENT.ATIVOS | B46: ativos | C46: Definir, validar e manter: Ativos | E46: alta
A47: D13-DOC-GTM-001.CONTENT.CAMPANHA | B47: campanha | C47: Definir, validar e manter: Campanha | E47: baixa
... A67: D13-DOC-GTM-001.GATES.CRITERIO | B67: criterio | C67: Definir, validar e manter: Criterio | E67: baixa
A68: Domínio D14 — Vendas
A69: Artefato D14-DOC-PCV-001 — Plano Comercial e de Vendas
A70: D14-DOC-PCV-001.CUSTOMER.ICP | B70: icp | C70: Definir, validar e manter: Icp | E70: baixa
A71: D14-DOC-PCV-001.CUSTOMER.SEGMENTOS | B71: segmentos | C71: Definir, validar e manter: Segmentos | E71: baixa
A72: D14-DOC-PCV-001.OFFERS.PRODUTO | B72: produto | C72: Definir, validar e manter: Produto | E72: baixa
A73: D14-DOC-PCV-001.OFFERS.PACOTE | B73: pacote | C73: Definir, validar e manter: Pacote | E73: alta
A74: D14-DOC-PCV-001.PRICING.PRECO | B74: preco | C74: Definir, validar e manter: Preco | E74: alta
A75: D14-DOC-PCV-001.PRICING.DESCONTO | B75: desconto | C75: Definir, validar e manter: Desconto | E75: baixa
...

Sheet 01_Formulario_A02
F2: Progresso de preenchimento | G2: =COUNTA(D7:D125)&" / 113"
A4: A02 — Produto e Experiência
A5: ID | B5: Campo | C5: O que preencher | D5: Resposta | E5: Exemplo (referência)
A6: Domínio D10 — Gestão de Produto
A7: Artefato D10-DOC-DRP-001 — Documento de Requisitos de Produto
A8: D10-DOC-DRP-001.PROBLEM.PROBLEMA | B8: problema | C8: Definir, validar e manter: Problema | E8: baixa
A9: D10-DOC-DRP-001.PROBLEM.EVIDENCIA | B9: evidencia | C9: Definir, validar e manter: Evidencia | E9: baixa
A10: D10-DOC-DRP-001.PROBLEM.IMPACTO | B10: impacto | C10: Definir, validar e manter: Impacto | E10: baixa
A11: D10-DOC-DRP-001.AUDIENCE.USUARIOS | B11: usuarios | C11: Definir, validar e manter: Usuarios | E11: baixa
A12: D10-DOC-DRP-001.AUDIENCE.CLIENTES | B12: clientes | C12: Definir, validar e manter: Clientes | E12: baixa
A13: D10-DOC-DRP-001.AUDIENCE.ICP | B13: icp | C13: Definir, validar e manter: Icp | E13: baixa
A14: D10-DOC-DRP-001.JTBD.SITUACAO | B14: situacao | C14: Definir, validar e manter: Situacao | E14: baixa
A15: D10-DOC-DRP-001.JTBD.TRABALHO | B15: trabalho | C15: Definir, validar e manter: Trabalho | E15: baixa
A16: D10-DOC-DRP-001.JTBD.OUTCOME | B16: outcome | C16: Definir, validar e manter: Outcome | E16: baixa
A17: D10-DOC-DRP-001.VALUE.PROPOSTA_DE_VALOR | B17: proposta_de_valor | C17: Definir, validar e manter: Proposta De Valor | E17: baixa
A18: D10-DOC-DRP-001.GOALS.OBJETIVOS | B18: objetivos | C18: Definir, validar e manter: Objetivos | E18: baixa
A19: D10-DOC-DRP-001.GOALS.METRICAS | B19: metricas | C19: Definir, validar e manter: Metricas | E19: baixa
... A35: D10-DOC-DRP-001.RISKS.MITIGACAO | B35: mitigacao | C35: Definir, validar e manter: Mitigacao | E35: baixa
A36: Artefato D10-DOC-PRD-001 — Requisitos Integrados dos Produtos
A37: D10-DOC-PRD-001.SCHEMA.PRODUCT_ID | B37: product_id | C37: Definir, validar e manter: Product ID | E37: baixa
A38: D10-DOC-PRD-001.SCHEMA.PRODUCT_NAME | B38: product_name | C38: Definir, validar e manter: Product Name | E38: baixa
A39: D10-DOC-PRD-001.SCHEMA.PROBLEM | B39: problem | C39: Definir, validar e manter: Problem | E39: baixa
A40: D10-DOC-PRD-001.SCHEMA.TARGET_USER | B40: target_user | C40: Definir, validar e manter: Target User | E40: baixa
A41: D10-DOC-PRD-001.SCHEMA.JTBD | B41: jtbd | C41: Definir, validar e manter: JTBD | E41: baixa
A42: D10-DOC-PRD-001.SCHEMA.GOALS | B42: goals | C42: Definir, validar e manter: Goals | E42: baixa
A43: D10-DOC-PRD-001.SCHEMA.NON_GOALS | B43: non_goals | C43: Definir, validar e manter: Non Goals | E43: baixa
A44: D10-DOC-PRD-001.SCHEMA.USE_CASES | B44: use_cases | C44: Definir, validar e manter: Use Cases | E44: baixa
A45: D10-DOC-PRD-001.SCHEMA.USER_STORIES | B45: user_stories | C45: Definir, validar e manter: User Stories | E45: baixa
A46: D10-DOC-PRD-001.SCHEMA.FUNCTIONAL_REQUIREMENTS | B46: functional_requirements | C46: Definir, validar e manter: Functional Requirements | E46: baixa
A47: D10-DOC-PRD-001.SCHEMA.NON_FUNCTIONAL_REQUIREMENTS | B47: non_functional_requirements | C47: Definir, validar e manter: Non Functional Requirements | E47: baixa
A48: D10-DOC-PRD-001.SCHEMA.USER_FLOWS | B48: user_flows | C48: Definir, validar e manter: User Flows | E48: baixa
... A59: D10-DOC-PRD-001.SCHEMA.RELEASE_CRITERIA | B59: release_criteria | C59: Definir, validar e manter: Release Criteria | E59: baixa
A60: Domínio D11 — Experiência e Projeto
A61: Artefato D11-DOC-EEP-001 — Especificação de Experiência e Projeto
A62: D11-DOC-EEP-001.USER_RESEARCH.EVIDENCIAS | B62: evidencias | C62: Definir, validar e manter: Evidencias | E62: baixa
A63: D11-DOC-EEP-001.USER_RESEARCH.NECESSIDADES | B63: necessidades | C63: Definir, validar e manter: Necessidades | E63: baixa
A64: D11-DOC-EEP-001.PERSONAS.PERFIL | B64: perfil | C64: Definir, validar e manter: Perfil | E64: baixa
A65: D11-DOC-EEP-001.PERSONAS.CONTEXTO | B65: contexto | C65: Definir, validar e manter: Contexto | E65: baixa
A66: D11-DOC-EEP-001.JOURNEYS.ETAPA | B66: etapa | C66: Definir, validar e manter: Etapa | E66: baixa
A67: D11-DOC-EEP-001.JOURNEYS.ACAO | B67: acao | C67: Definir, validar e manter: Acao | E67: baixa
...

Sheet 01_Formulario_A03
F2: Progresso de preenchimento | G2: =COUNTA(D7:D6)&" / 0"
A4: A03 — Handoff Produto → Engenharia
A5: ID | B5: Campo | C5: O que preencher | D5: Resposta | E5: Exemplo (referência)

Sheet 01_Formulario_A04
F2: Progresso de preenchimento | G2: =COUNTA(D7:D56)&" / 48"
A4: A04 — Arquitetura, Engenharia e Implementação
A5: ID | B5: Campo | C5: O que preencher | D5: Resposta | E5: Exemplo (referência)
A6: Domínio D12 — Engenharia
A7: Artefato D12-DOC-ETE-001 — Especificação Técnica de Engenharia
A8: D12-DOC-ETE-001.ARCHITECTURE.VISAO_GERAL | B8: visao_geral | C8: Definir, validar e manter: Visao Geral | E8: baixa
A9: D12-DOC-ETE-001.ARCHITECTURE.DIAGRAMAS | B9: diagramas | C9: Definir, validar e manter: Diagramas | E9: baixa
A10: D12-DOC-ETE-001.REPOSITORIES.REPOSITORIO | B10: repositorio | C10: Definir, validar e manter: Repositorio | E10: baixa
A11: D12-DOC-ETE-001.REPOSITORIES.BRANCH | B11: branch | C11: Definir, validar e manter: Branch | E11: baixa
A12: D12-DOC-ETE-001.REPOSITORIES.FINALIDADE | B12: finalidade | C12: Definir, validar e manter: Finalidade | E12: baixa
A13: D12-DOC-ETE-001.STACK.FRAMEWORKS | B13: frameworks | C13: Definir, validar e manter: Frameworks | E13: alta
A14: D12-DOC-ETE-001.STACK.LINGUAGENS | B14: linguagens | C14: Definir, validar e manter: Linguagens | E14: baixa
A15: D12-DOC-ETE-001.STACK.RUNTIME | B15: runtime | C15: Definir, validar e manter: Runtime | E15: baixa
A16: D12-DOC-ETE-001.APPLICATIONS.APP | B16: app | C16: Definir, validar e manter: App | E16: baixa
A17: D12-DOC-ETE-001.APPLICATIONS.RESPONSABILIDADE | B17: responsabilidade | C17: Definir, validar e manter: Responsabilidade | E17: baixa
A18: D12-DOC-ETE-001.PACKAGES.PACKAGE | B18: package | C18: Definir, validar e manter: Package | E18: alta
A19: D12-DOC-ETE-001.PACKAGES.RESPONSABILIDADE | B19: responsabilidade | C19: Definir, validar e manter: Responsabilidade | E19: baixa
... A55: D12-DOC-ETE-001.ADR_LINKS.DECISOES_ARQUITETURAIS | B55: decisoes_arquiteturais | C55: Definir, validar e manter: Decisoes Arquiteturais | E55: alta

Sheet 01_Formulario_A05
F2: Progresso de preenchimento | G2: =COUNTA(D7:D52)&" / 43"
A4: A05 — Operações, Plataforma, Deploy e Segurança
A5: ID | B5: Campo | C5: O que preencher | D5: Resposta | E5: Exemplo (referência)
A6: Domínio D08 — Operações
A7: Artefato D08-DOC-MOP-001 — Manual de Operações
A8: D08-DOC-MOP-001.OPERATING_MODEL.SERVICOS | B8: servicos | C8: Definir, validar e manter: Servicos | E8: baixa
A9: D08-DOC-MOP-001.OPERATING_MODEL.PROCESSOS | B9: processos | C9: Definir, validar e manter: Processos | E9: alta
A10: D08-DOC-MOP-001.PROCESS_INVENTORY.PROCESSO | B10: processo | C10: Definir, validar e manter: Processo | E10: alta
A11: D08-DOC-MOP-001.PROCESS_INVENTORY.OBJETIVO | B11: objetivo | C11: Definir, validar e manter: Objetivo | E11: baixa
A12: D08-DOC-MOP-001.PROCESS_INVENTORY.OWNER | B12: owner | C12: Definir, validar e manter: Owner | E12: baixa
A13: D08-DOC-MOP-001.INPUTS.ENTRADA | B13: entrada | C13: Definir, validar e manter: Entrada | E13: baixa
A14: D08-DOC-MOP-001.INPUTS.ORIGEM | B14: origem | C14: Definir, validar e manter: Origem | E14: baixa
A15: D08-DOC-MOP-001.PROCEDURES.ETAPAS | B15: etapas | C15: Definir, validar e manter: Etapas | E15: baixa
A16: D08-DOC-MOP-001.PROCEDURES.REGRA | B16: regra | C16: Definir, validar e manter: Regra | E16: baixa
A17: D08-DOC-MOP-001.OUTPUTS.SAIDA | B17: saida | C17: Definir, validar e manter: Saida | E17: baixa
A18: D08-DOC-MOP-001.OUTPUTS.CONSUMIDOR | B18: consumidor | C18: Definir, validar e manter: Consumidor | E18: baixa
A19: D08-DOC-MOP-001.ROLES.EXECUTOR | B19: executor | C19: Definir, validar e manter: Executor | E19: baixa
... A34: D08-DOC-MOP-001.METRICS.QUALIDADE | B34: qualidade | C34: Definir, validar e manter: Qualidade | E34: alta
A35: Artefato D08-DOC-RUN-001 — Runbook Operacional do Ecossistema
A36: D08-DOC-RUN-001.SCHEMA.RUNBOOK_ID | B36: runbook_id | C36: Definir, validar e manter: Runbook ID | E36: baixa
A37: D08-DOC-RUN-001.SCHEMA.NOME | B37: nome | C37: Definir, validar e manter: Nome | E37: baixa
A38: D08-DOC-RUN-001.SCHEMA.OBJETIVO | B38: objetivo | C38: Definir, validar e manter: Objetivo | E38: baixa
A39: D08-DOC-RUN-001.SCHEMA.TRIGGER | B39: trigger | C39: Definir, validar e manter: Trigger | E39: baixa
A40: D08-DOC-RUN-001.SCHEMA.PRECONDICOES | B40: precondicoes | C40: Definir, validar e manter: Precondicoes | E40: baixa
A41: D08-DOC-RUN-001.SCHEMA.SISTEMAS | B41: sistemas | C41: Definir, validar e manter: Sistemas | E41: baixa
A42: D08-DOC-RUN-001.SCHEMA.CREDENCIAIS_NECESSARIAS | B42: credenciais_necessarias | C42: Definir, validar e manter: Credenciais Necessarias | E42: baixa
A43: D08-DOC-RUN-001.SCHEMA.PASSOS | B43: passos | C43: Definir, validar e manter: Passos | E43: baixa
A44: D08-DOC-RUN-001.SCHEMA.RESULTADO_ESPERADO | B44: resultado_esperado | C44: Definir, validar e manter: Resultado Esperado | E44: baixa
A45: D08-DOC-RUN-001.SCHEMA.VERIFICACAO | B45: verificacao | C45: Definir, validar e manter: Verificacao | E45: media
A46: D08-DOC-RUN-001.SCHEMA.EVIDENCIA | B46: evidencia | C46: Definir, validar e manter: Evidencia | E46: baixa
A47: D08-DOC-RUN-001.SCHEMA.EXCECOES | B47: excecoes | C47: Definir, validar e manter: Excecoes | E47: alta
... A51: D08-DOC-RUN-001.SCHEMA.FREQUENCIA | B51: frequencia | C51: Definir, validar e manter: Frequencia | E51: baixa

Sheet 01_Formulario_A06
F2: Progresso de preenchimento | G2: =COUNTA(D7:D157)&" / 142"
A4: A06 — Dados, Pesquisa e Conhecimento
A5: ID | B5: Campo | C5: O que preencher | D5: Resposta | E5: Exemplo (referência)
A6: Domínio D05 — Dados
A7: Artefato D05-DOC-EPGD-001 — Estratégia e Plano de Gestão de Dados
A8: D05-DOC-EPGD-001.DATA_DOMAINS.DOMINIO | B8: dominio | C8: Definir, validar e manter: Dominio | E8: baixa
A9: D05-DOC-EPGD-001.DATA_DOMAINS.DESCRICAO | B9: descricao | C9: Definir, validar e manter: Descricao | E9: baixa
A10: D05-DOC-EPGD-001.DATA_DOMAINS.OWNER | B10: owner | C10: Definir, validar e manter: Owner | E10: baixa
A11: D05-DOC-EPGD-001.SOURCES.FONTE | B11: fonte | C11: Definir, validar e manter: Fonte | E11: baixa
A12: D05-DOC-EPGD-001.SOURCES.SISTEMA | B12: sistema | C12: Definir, validar e manter: Sistema | E12: baixa
A13: D05-DOC-EPGD-001.SOURCES.ORIGEM | B13: origem | C13: Definir, validar e manter: Origem | E13: baixa
A14: D05-DOC-EPGD-001.INGESTION.METODO | B14: metodo | C14: Definir, validar e manter: Metodo | E14: baixa
A15: D05-DOC-EPGD-001.INGESTION.FREQUENCIA | B15: frequencia | C15: Definir, validar e manter: Frequencia | E15: baixa
A16: D05-DOC-EPGD-001.STORAGE.BANCO | B16: banco | C16: Definir, validar e manter: Banco | E16: baixa
A17: D05-DOC-EPGD-001.STORAGE.REPOSITORIO | B17: repositorio | C17: Definir, validar e manter: Repositorio | E17: baixa
A18: D05-DOC-EPGD-001.STORAGE.FORMATO | B18: formato | C18: Definir, validar e manter: Formato | E18: baixa
A19: D05-DOC-EPGD-001.SCHEMAS.SCHEMA | B19: schema | C19: Definir, validar e manter: Schema | E19: baixa
... A43: D05-DOC-EPGD-001.GOVERNANCE.APROVACAO | B43: aprovacao | C43: Definir, validar e manter: Aprovacao | E43: baixa
A44: Artefato D05-DOC-DCM-001 — Dicionário de Dados e Catálogo de Métricas
A45: D05-DOC-DCM-001.SCHEMA.METRIC_OR_FIELD_ID | B45: metric_or_field_id | C45: Definir, validar e manter: Metric Or Field ID | E45: baixa
A46: D05-DOC-DCM-001.SCHEMA.NOME | B46: nome | C46: Definir, validar e manter: Nome | E46: baixa
A47: D05-DOC-DCM-001.SCHEMA.TIPO | B47: tipo | C47: Definir, validar e manter: Tipo | E47: baixa
A48: D05-DOC-DCM-001.SCHEMA.DEFINICAO | B48: definicao | C48: Definir, validar e manter: Definicao | E48: baixa
A49: D05-DOC-DCM-001.SCHEMA.FORMULA | B49: formula | C49: Definir, validar e manter: Formula | E49: baixa
A50: D05-DOC-DCM-001.SCHEMA.UNIDADE | B50: unidade | C50: Definir, validar e manter: Unidade | E50: baixa
A51: D05-DOC-DCM-001.SCHEMA.GRANULARIDADE | B51: granularidade | C51: Definir, validar e manter: Granularidade | E51: baixa
A52: D05-DOC-DCM-001.SCHEMA.FONTE | B52: fonte | C52: Definir, validar e manter: Fonte | E52: baixa
A53: D05-DOC-DCM-001.SCHEMA.TABELA_DATASET | B53: tabela_dataset | C53: Definir, validar e manter: Tabela Dataset | E53: baixa
A54: D05-DOC-DCM-001.SCHEMA.CAMPO_EVENTO | B54: campo_evento | C54: Definir, validar e manter: Campo Evento | E54: baixa
A55: D05-DOC-DCM-001.SCHEMA.DIMENSOES | B55: dimensoes | C55: Definir, validar e manter: Dimensoes | E55: baixa
A56: D05-DOC-DCM-001.SCHEMA.OWNER | B56: owner | C56: Definir, validar e manter: Owner | E56: baixa
... A62: D05-DOC-DCM-001.SCHEMA.CONSUMIDORES | B62: consumidores | C62: Definir, validar e manter: Consumidores | E62: baixa
A63: Domínio D06 — Conhecimento e Busca Corporativa
A64: Artefato D06-DOC-EGC-001 — Estratégia de Gestão do Conhecimento
A65: D06-DOC-EGC-001.TAXONOMY.DOMINIOS | B65: dominios | C65: Definir, validar e manter: Dominios | E65: alta
A66: D06-DOC-EGC-001.TAXONOMY.SUBAREAS | B66: subareas | C66: Definir, validar e manter: Subareas | E66: baixa
A67: D06-DOC-EGC-001.TAXONOMY.CLASSES_DOCUMENTAIS | B67: classes_documentais | C67: Definir, validar e manter: Classes Documentais | E67: baixa
A68: D06-DOC-EGC-001.ONTOLOGY.OBJETOS | B68: objetos | C68: Definir, validar e manter: Objetos | E68: baixa
A69: D06-DOC-EGC-001.ONTOLOGY.RELACOES | B69: relacoes | C69: Definir, validar e manter: Relacoes | E69: baixa
A70: D06-DOC-EGC-001.REPOSITORIES.REPOSITORIO | B70: repositorio | C70: Definir, validar e manter: Repositorio | E70: baixa
...

Sheet 01_Formulario_A07
F2: Progresso de preenchimento | G2: =COUNTA(D7:D47)&" / 39"
A4: A07 — Corporativo e Suporte
A5: ID | B5: Campo | C5: O que preencher | D5: Resposta | E5: Exemplo (referência)
A6: Domínio D04 — Pessoas e Recursos Humanos
A7: Artefato D04-DOC-PPC-001 — Plano de Pessoas e Capacidade
A8: D04-DOC-PPC-001.ORGANIZATION.ESTRUTURA | B8: estrutura | C8: Definir, validar e manter: Estrutura | E8: baixa
A9: D04-DOC-PPC-001.ORGANIZATION.EQUIPES | B9: equipes | C9: Definir, validar e manter: Equipes | E9: baixa
A10: D04-DOC-PPC-001.ORGANIZATION.FUNCOES | B10: funcoes | C10: Definir, validar e manter: Funcoes | E10: baixa
A11: D04-DOC-PPC-001.ROLES.PAPEL | B11: papel | C11: Definir, validar e manter: Papel | E11: baixa
A12: D04-DOC-PPC-001.ROLES.RESPONSABILIDADES | B12: responsabilidades | C12: Definir, validar e manter: Responsabilidades | E12: baixa
A13: D04-DOC-PPC-001.ROLES.AUTORIDADE | B13: autoridade | C13: Definir, validar e manter: Autoridade | E13: baixa
A14: D04-DOC-PPC-001.RACI.ATIVIDADE | B14: atividade | C14: Definir, validar e manter: Atividade | E14: baixa
A15: D04-DOC-PPC-001.RACI.RESPONSAVEL | B15: responsavel | C15: Definir, validar e manter: Responsavel | E15: media
A16: D04-DOC-PPC-001.RACI.APROVADOR | B16: aprovador | C16: Definir, validar e manter: Aprovador | E16: media
A17: D04-DOC-PPC-001.RACI.CONSULTADO | B17: consultado | C17: Definir, validar e manter: Consultado | E17: media
A18: D04-DOC-PPC-001.RACI.INFORMADO | B18: informado | C18: Definir, validar e manter: Informado | E18: media
A19: D04-DOC-PPC-001.PEOPLE.PESSOA | B19: pessoa | C19: Definir, validar e manter: Pessoa | E19: media
... A46: D04-DOC-PPC-001.METRICS.GAPS | B46: gaps | C46: Definir, validar e manter: Gaps | E46: baixa

Sheet 01_Formulario_A08
F2: Progresso de preenchimento | G2: =COUNTA(D7:D44)&" / 36"
A4: A08 — Conteúdo, Comunicação e Growth
A5: ID | B5: Campo | C5: O que preencher | D5: Resposta | E5: Exemplo (referência)
A6: Domínio D16 — Mídias Sociais e Distribuição Digital (alias: Mídias Sociais e Estratégias)
A7: Artefato D16-DOC-PEM-001 — Plano Estratégico de Mídias Sociais
A8: D16-DOC-PEM-001.OBJECTIVES.OBJETIVOS | B8: objetivos | C8: Definir, validar e manter: Objetivos | E8: baixa
A9: D16-DOC-PEM-001.AUDIENCE.PUBLICOS | B9: publicos | C9: Definir, validar e manter: Publicos | E9: baixa
A10: D16-DOC-PEM-001.CHANNELS.CANAL | B10: canal | C10: Definir, validar e manter: Canal | E10: baixa
A11: D16-DOC-PEM-001.CHANNELS.FUNCAO | B11: funcao | C11: Definir, validar e manter: Funcao | E11: baixa
A12: D16-DOC-PEM-001.CONTENT_PILLARS.PILAR | B12: pilar | C12: Definir, validar e manter: Pilar | E12: alta
A13: D16-DOC-PEM-001.CONTENT_PILLARS.TESE | B13: tese | C13: Definir, validar e manter: Tese | E13: baixa
A14: D16-DOC-PEM-001.FORMATS.ARTIGO | B14: artigo | C14: Definir, validar e manter: Artigo | E14: baixa
A15: D16-DOC-PEM-001.FORMATS.VIDEO | B15: video | C15: Definir, validar e manter: Video | E15: baixa
A16: D16-DOC-PEM-001.FORMATS.CARROSSEL | B16: carrossel | C16: Definir, validar e manter: Carrossel | E16: baixa
A17: D16-DOC-PEM-001.FORMATS.STORY | B17: story | C17: Definir, validar e manter: Story | E17: baixa
A18: D16-DOC-PEM-001.FORMATS.NEWSLETTER | B18: newsletter | C18: Definir, validar e manter: Newsletter | E18: baixa
A19: D16-DOC-PEM-001.EDITORIAL_CALENDAR.DATA | B19: data | C19: Definir, validar e manter: Data | E19: baixa
... A43: D16-DOC-PEM-001.BRAND_COMPLIANCE.CLAIMS | B43: claims | C43: Definir, validar e manter: Claims | E43: baixa

Sheet 01_Formulario_A09
F2: Progresso de preenchimento | G2: =COUNTA(D7:D68)&" / 59"
A4: A09 — Execução e Planejamento do Trabalho
A5: ID | B5: Campo | C5: O que preencher | D5: Resposta | E5: Exemplo (referência)
A6: Domínio D07 — Produtividade e Execução
A7: Artefato D07-DOC-PEX-001 — Plano de Execução
A8: D07-DOC-PEX-001.OBJECTIVES.OBJETIVO | B8: objetivo | C8: Definir, validar e manter: Objetivo | E8: baixa
A9: D07-DOC-PEX-001.OBJECTIVES.RESULTADO | B9: resultado | C9: Definir, validar e manter: Resultado | E9: baixa
A10: D07-DOC-PEX-001.DELIVERABLES.ENTREGAVEL | B10: entregavel | C10: Definir, validar e manter: Entregavel | E10: baixa
A11: D07-DOC-PEX-001.DELIVERABLES.DOD | B11: dod | C11: Definir, validar e manter: Dod | E11: baixa
A12: D07-DOC-PEX-001.DELIVERABLES.EVIDENCIA | B12: evidencia | C12: Definir, validar e manter: Evidencia | E12: baixa
A13: D07-DOC-PEX-001.PORTFOLIO.PROJETO | B13: projeto | C13: Definir, validar e manter: Projeto | E13: baixa
A14: D07-DOC-PEX-001.PORTFOLIO.PRIORIDADE | B14: prioridade | C14: Definir, validar e manter: Prioridade | E14: media
A15: D07-DOC-PEX-001.PORTFOLIO.ESTADO | B15: estado | C15: Definir, validar e manter: Estado | E15: baixa
A16: D07-DOC-PEX-001.DEPENDENCIES.UPSTREAM | B16: upstream | C16: Definir, validar e manter: Upstream | E16: baixa
A17: D07-DOC-PEX-001.DEPENDENCIES.DOWNSTREAM | B17: downstream | C17: Definir, validar e manter: Downstream | E17: baixa
A18: D07-DOC-PEX-001.CAPACITY.CAPACIDADE_BRUTA | B18: capacidade_bruta | C18: Definir, validar e manter: Capacidade Bruta | E18: alta
A19: D07-DOC-PEX-001.CAPACITY.FIXA | B19: fixa | C19: Definir, validar e manter: Fixa | E19: baixa
... A39: D07-DOC-PEX-001.PROGRESS.RESTANTE | B39: restante | C39: Definir, validar e manter: Restante | E39: baixa
A40: Artefato D07-DOC-PIM-001 — Plano de Implementação e Marcos
A41: D07-DOC-PIM-001.IMPLEMENTATION_STRATEGY.ABORDAGEM | B41: abordagem | C41: Definir, validar e manter: Abordagem | E41: baixa
A42: D07-DOC-PIM-001.IMPLEMENTATION_STRATEGY.ONDAS | B42: ondas | C42: Definir, validar e manter: Ondas | E42: baixa
A43: D07-DOC-PIM-001.MILESTONES.MARCO | B43: marco | C43: Definir, validar e manter: Marco | E43: alta
A44: D07-DOC-PIM-001.MILESTONES.RESULTADO | B44: resultado | C44: Definir, validar e manter: Resultado | E44: baixa
A45: D07-DOC-PIM-001.MILESTONES.CRITERIO | B45: criterio | C45: Definir, validar e manter: Criterio | E45: baixa
A46: D07-DOC-PIM-001.WORK_PACKAGES.PACOTE | B46: pacote | C46: Definir, validar e manter: Pacote | E46: baixa
A47: D07-DOC-PIM-001.WORK_PACKAGES.ENTREGAVEL | B47: entregavel | C47: Definir, validar e manter: Entregavel | E47: baixa
A48: D07-DOC-PIM-001.DEPENDENCIES.DEPENDENCIA | B48: dependencia | C48: Definir, validar e manter: Dependencia | E48: baixa
A49: D07-DOC-PIM-001.DEPENDENCIES.PRECONDICAO | B49: precondicao | C49: Definir, validar e manter: Precondicao | E49: baixa
A50: D07-DOC-PIM-001.RESOURCES.PESSOA | B50: pessoa | C50: Definir, validar e manter: Pessoa | E50: baixa
A51: D07-DOC-PIM-001.RESOURCES.SISTEMA | B51: sistema | C51: Definir, validar e manter: Sistema | E51: baixa
A52: D07-DOC-PIM-001.RESOURCES.RECURSO | B52: recurso | C52: Definir, validar e manter: Recurso | E52: baixa
... A67: D07-DOC-PIM-001.ROLLBACK.PROCEDIMENTO | B67: procedimento | C67: Definir, validar e manter: Procedimento | E67: baixa

Sheet 01_Formulario_A10
F2: Progresso de preenchimento | G2: =COUNTA(D7:D105)&" / 93"
A4: A10 — Documentação e Governança do Conhecimento
A5: ID | B5: Campo | C5: O que preencher | D5: Resposta | E5: Exemplo (referência)
A6: Domínio D21 — Workbook
A7: Artefato D21-DOC-PWB-001 — Plano de Workbooks
A8: D21-DOC-PWB-001.WORKBOOK_CATALOG.WORKBOOK_ID | B8: workbook_id | C8: Definir, validar e manter: Workbook ID | E8: alta
A9: D21-DOC-PWB-001.WORKBOOK_CATALOG.NOME | B9: nome | C9: Definir, validar e manter: Nome | E9: baixa
A10: D21-DOC-PWB-001.PURPOSE.OBJETIVO | B10: objetivo | C10: Definir, validar e manter: Objetivo | E10: baixa
A11: D21-DOC-PWB-001.PURPOSE.USUARIO | B11: usuario | C11: Definir, validar e manter: Usuario | E11: baixa
A12: D21-DOC-PWB-001.SOURCE_DATA.FONTE | B12: fonte | C12: Definir, validar e manter: Fonte | E12: baixa
A13: D21-DOC-PWB-001.SOURCE_DATA.ATUALIZACAO | B13: atualizacao | C13: Definir, validar e manter: Atualizacao | E13: baixa
A14: D21-DOC-PWB-001.SHEETS.ABA | B14: aba | C14: Definir, validar e manter: Aba | E14: baixa
A15: D21-DOC-PWB-001.SHEETS.FINALIDADE | B15: finalidade | C15: Definir, validar e manter: Finalidade | E15: baixa
A16: D21-DOC-PWB-001.FIELDS.CAMPO | B16: campo | C16: Definir, validar e manter: Campo | E16: baixa
A17: D21-DOC-PWB-001.FIELDS.DEFINICAO | B17: definicao | C17: Definir, validar e manter: Definicao | E17: baixa
A18: D21-DOC-PWB-001.FORMULAS.FORMULA | B18: formula | C18: Definir, validar e manter: Formula | E18: baixa
A19: D21-DOC-PWB-001.FORMULAS.LOGICA | B19: logica | C19: Definir, validar e manter: Logica | E19: baixa
... A37: D21-DOC-PWB-001.EVIDENCE.RASTREABILIDADE | B37: rastreabilidade | C37: Definir, validar e manter: Rastreabilidade | E37: baixa
A38: Domínio D22 — Decision and Register Log
A39: Artefato D22-DOC-DRL-001 — Decision and Register Log do Ecossistema
A40: D22-DOC-DRL-001.SCHEMA.DECISION_ID | B40: decision_id | C40: Definir, validar e manter: Decision ID | E40: baixa
A41: D22-DOC-DRL-001.SCHEMA.TITLE | B41: title | C41: Definir, validar e manter: Title | E41: baixa
A42: D22-DOC-DRL-001.SCHEMA.DOMAIN | B42: domain | C42: Definir, validar e manter: Domain | E42: baixa
A43: D22-DOC-DRL-001.SCHEMA.CONTEXT | B43: context | C43: Definir, validar e manter: Context | E43: baixa
A44: D22-DOC-DRL-001.SCHEMA.PROBLEM | B44: problem | C44: Definir, validar e manter: Problem | E44: baixa
A45: D22-DOC-DRL-001.SCHEMA.DECISION_REQUIRED | B45: decision_required | C45: Definir, validar e manter: Decision Required | E45: baixa
A46: D22-DOC-DRL-001.SCHEMA.OPTIONS_CONSIDERED | B46: options_considered | C46: Definir, validar e manter: Options Considered | E46: baixa
A47: D22-DOC-DRL-001.SCHEMA.EVALUATION_CRITERIA | B47: evaluation_criteria | C47: Definir, validar e manter: Evaluation Criteria | E47: baixa
A48: D22-DOC-DRL-001.SCHEMA.SELECTED_OPTION | B48: selected_option | C48: Definir, validar e manter: Selected Option | E48: baixa
A49: D22-DOC-DRL-001.SCHEMA.RATIONALE | B49: rationale | C49: Definir, validar e manter: Rationale | E49: baixa
A50: D22-DOC-DRL-001.SCHEMA.EVIDENCE | B50: evidence | C50: Definir, validar e manter: Evidence | E50: baixa
A51: D22-DOC-DRL-001.SCHEMA.OWNER | B51: owner | C51: Definir, validar e manter: Owner | E51: baixa
... A62: D22-DOC-DRL-001.SCHEMA.SUPERSEDED_BY | B62: superseded_by | C62: Definir, validar e manter: Superseded By | E62: baixa
A63: Domínio D23 — Blueprints
A64: Artefato D23-DOC-PBL-001 — Plano de Blueprints
A65: D23-DOC-PBL-001.BLUEPRINT_CATALOG.BLUEPRINT_ID | B65: blueprint_id | C65: Definir, validar e manter: Blueprint ID | E65: baixa
A66: D23-DOC-PBL-001.BLUEPRINT_CATALOG.NOME | B66: nome | C66: Definir, validar e manter: Nome | E66: baixa
A67: D23-DOC-PBL-001.BLUEPRINT_CATALOG.DOMINIO | B67: dominio | C67: Definir, validar e manter: Dominio | E67: baixa
A68: D23-DOC-PBL-001.PROBLEM.PROBLEMA | B68: problema | C68: Definir, validar e manter: Problema | E68: baixa
A69: D23-DOC-PBL-001.PROBLEM.EVIDENCIA | B69: evidencia | C69: Definir, validar e manter: Evidencia | E69: baixa
...

Sheet 01_Formulario_A11
F2: Progresso de preenchimento | G2: =COUNTA(D7:D86)&" / 76"
A4: A11 — Ferramentas, IA e Ativos Reutilizáveis
A5: ID | B5: Campo | C5: O que preencher | D5: Resposta | E5: Exemplo (referência)
A6: Domínio D19 — Assets e CTAs
A7: Artefato D19-DOC-PAC-001 — Plano de Assets e CTAs
A8: D19-DOC-PAC-001.ASSET_INVENTORY.ASSET_ID | B8: asset_id | C8: Definir, validar e manter: Asset ID | E8: baixa
A9: D19-DOC-PAC-001.ASSET_INVENTORY.NOME | B9: nome | C9: Definir, validar e manter: Nome | E9: baixa
A10: D19-DOC-PAC-001.ASSET_INVENTORY.TIPO | B10: tipo | C10: Definir, validar e manter: Tipo | E10: alta
A11: D19-DOC-PAC-001.PURPOSE.OBJETIVO | B11: objetivo | C11: Definir, validar e manter: Objetivo | E11: baixa
A12: D19-DOC-PAC-001.PURPOSE.CAMPANHA | B12: campanha | C12: Definir, validar e manter: Campanha | E12: baixa
A13: D19-DOC-PAC-001.PURPOSE.PRODUTO | B13: produto | C13: Definir, validar e manter: Produto | E13: baixa
A14: D19-DOC-PAC-001.SOURCE.ORIGEM | B14: origem | C14: Definir, validar e manter: Origem | E14: baixa
A15: D19-DOC-PAC-001.SOURCE.DOCUMENTO_FONTE | B15: documento_fonte | C15: Definir, validar e manter: Documento Fonte | E15: baixa
A16: D19-DOC-PAC-001.FORMAT.ARQUIVO | B16: arquivo | C16: Definir, validar e manter: Arquivo | E16: baixa
A17: D19-DOC-PAC-001.FORMAT.DIMENSAO | B17: dimensao | C17: Definir, validar e manter: Dimensao | E17: baixa
A18: D19-DOC-PAC-001.FORMAT.CANAL | B18: canal | C18: Definir, validar e manter: Canal | E18: baixa
A19: D19-DOC-PAC-001.CONTENT.HEADLINE | B19: headline | C19: Definir, validar e manter: Headline | E19: baixa
... A44: D19-DOC-PAC-001.REUSE.DERIVADOS | B44: derivados | C44: Definir, validar e manter: Derivados | E44: baixa
A45: Domínio D20 — Plataformas e Repositórios
A46: Artefato D20-DOC-PPR-001 — Plano de Plataformas e Repositórios
A47: D20-DOC-PPR-001.SYSTEMS.PLATAFORMA | B47: plataforma | C47: Definir, validar e manter: Plataforma | E47: alta
A48: D20-DOC-PPR-001.SYSTEMS.FINALIDADE | B48: finalidade | C48: Definir, validar e manter: Finalidade | E48: baixa
A49: D20-DOC-PPR-001.ACCOUNTS.CONTA | B49: conta | C49: Definir, validar e manter: Conta | E49: baixa
A50: D20-DOC-PPR-001.ACCOUNTS.ORGANIZACAO | B50: organizacao | C50: Definir, validar e manter: Organizacao | E50: baixa
A51: D20-DOC-PPR-001.REPOSITORIES.REPO | B51: repo | C51: Definir, validar e manter: Repo | E51: baixa
A52: D20-DOC-PPR-001.REPOSITORIES.OWNER | B52: owner | C52: Definir, validar e manter: Owner | E52: baixa
A53: D20-DOC-PPR-001.REPOSITORIES.FINALIDADE | B53: finalidade | C53: Definir, validar e manter: Finalidade | E53: baixa
A54: D20-DOC-PPR-001.BRANCHES.BRANCH | B54: branch | C54: Definir, validar e manter: Branch | E54: baixa
A55: D20-DOC-PPR-001.BRANCHES.FUNCAO | B55: funcao | C55: Definir, validar e manter: Funcao | E55: baixa
A56: D20-DOC-PPR-001.BRANCHES.PROTECAO | B56: protecao | C56: Definir, validar e manter: Protecao | E56: baixa
A57: D20-DOC-PPR-001.DIRECTORIES.PATH | B57: path | C57: Definir, validar e manter: Path | E57: baixa
A58: D20-DOC-PPR-001.DIRECTORIES.RESPONSABILIDADE | B58: responsabilidade | C58: Definir, validar e manter: Responsabilidade | E58: baixa
... A85: D20-DOC-PPR-001.MAINTENANCE.OWNER | B85: owner | C85: Definir, validar e manter: Owner | E85: baixa

Sheet 01_Formulario_A12
F2: Progresso de preenchimento | G2: =COUNTA(D7:D47)&" / 39"
A4: A12 — Stakeholders e Ecossistema
A5: ID | B5: Campo | C5: O que preencher | D5: Resposta | E5: Exemplo (referência)
A6: Domínio D17 — Emprego e Portfólio
A7: Artefato D17-DOC-PEP-001 — Plano de Emprego e Portfólio
A8: D17-DOC-PEP-001.OBJECTIVE.OBJETIVO_PROFISSIONAL | B8: objetivo_profissional | C8: Definir, validar e manter: Objetivo Profissional | E8: baixa
A9: D17-DOC-PEP-001.OBJECTIVE.HORIZONTE | B9: horizonte | C9: Definir, validar e manter: Horizonte | E9: baixa
A10: D17-DOC-PEP-001.POSITIONING.PROPOSTA_PROFISSIONAL | B10: proposta_profissional | C10: Definir, validar e manter: Proposta Profissional | E10: baixa
A11: D17-DOC-PEP-001.POSITIONING.ESPECIALIDADES | B11: especialidades | C11: Definir, validar e manter: Especialidades | E11: baixa
A12: D17-DOC-PEP-001.TARGET.CARGOS | B12: cargos | C12: Definir, validar e manter: Cargos | E12: baixa
A13: D17-DOC-PEP-001.TARGET.EMPRESAS | B13: empresas | C13: Definir, validar e manter: Empresas | E13: baixa
A14: D17-DOC-PEP-001.TARGET.CLIENTES | B14: clientes | C14: Definir, validar e manter: Clientes | E14: baixa
A15: D17-DOC-PEP-001.TARGET.MERCADOS | B15: mercados | C15: Definir, validar e manter: Mercados | E15: baixa
A16: D17-DOC-PEP-001.COMPETENCIES.COMPETENCIAS | B16: competencias | C16: Definir, validar e manter: Competencias | E16: baixa
A17: D17-DOC-PEP-001.COMPETENCIES.NIVEL | B17: nivel | C17: Definir, validar e manter: Nivel | E17: baixa
A18: D17-DOC-PEP-001.COMPETENCIES.EVIDENCIA | B18: evidencia | C18: Definir, validar e manter: Evidencia | E18: baixa
A19: D17-DOC-PEP-001.GAPS.LACUNA | B19: lacuna | C19: Definir, validar e manter: Lacuna | E19: baixa
... A46: D17-DOC-PEP-001.METRICS.CONVERSAO | B46: conversao | C46: Definir, validar e manter: Conversao | E46: baixa

Sheet 02_Visao_Programa
B2: Visão Programa — EXECUTAR
B4: Macroáreas | C4: =COUNTA('10_REG_Macroareas'!A2:A1000)
B5: Domínios | C5: =COUNTA('11_REG_Dominios'!A2:A1000)
B6: Itens de Portfólio | C6: =COUNTA('12_REG_Portfolio'!A2:A1000)
B7: Templates | C7: =COUNTA('13_REG_Templates'!A2:A1000)
B8: Artefatos | C8: =COUNTA('14_REG_Artefatos'!A2:A1000)
B9: Campos | C9: =COUNTA('15_REG_Campos'!A2:A2000)
B10: Dependências registradas | C10: =COUNTA('16_REG_Dependencias'!A2:A1000)
B11: Gates | C11: =COUNTA('17_REG_Gates'!A2:A1000)
B12: Gaps abertos | C12: =COUNTIFS('21_REG_Gaps'!E2:E1000,"OPEN")
B13: Conflitos abertos | C13: =COUNTIFS('22_REG_Conflitos'!H2:H1000,"ABERTO")

Sheet 03_Visao_Macroareas
B2: Visão Macroáreas — espelho narrativo (não editar; ver 01_Formulario_*)
A4: A00 — Governança, Estratégia e Gestão
A5: D01-DOC-DDE-001.IDENTITY.NOME_DO_ECOSSISTEMA | B5: nome_do_ecossistema | C5: =IFERROR(IF(INDEX('01_Formulario_A00'!$D:$D,MATCH("D01-DOC-DDE-001.IDENTITY.NOME_DO_ECOSSISTEMA",'01_Formulario_A00'!$A:$A,0))="","— (a preencher em 01_Formulario_A00)",INDEX('01_Formulario_A00'!$D:$D,MATCH("D01-DOC-DDE-001.IDENTITY.NOME_DO_ECOSSISTEMA",'01_Formulario_A00'!$A:$A,0))),"— (a preencher em 01_Formulario_A00)")
A6: D01-DOC-DDE-001.IDENTITY.DESCRICAO_EXECUTIVA | B6: descricao_executiva | C6: =IFERROR(IF(INDEX('01_Formulario_A00'!$D:$D,MATCH("D01-DOC-DDE-001.IDENTITY.DESCRICAO_EXECUTIVA",'01_Formulario_A00'!$A:$A,0))="","— (a preencher em 01_Formulario_A00)",INDEX('01_Formulario_A00'!$D:$D,MATCH("D01-DOC-DDE-001.IDENTITY.DESCRICAO_EXECUTIVA",'01_Formulario_A00'!$A:$A,0))),"— (a preencher em 01_Formulario_A00)")
A7: D01-DOC-DDE-001.IDENTITY.CONTEXTO | B7: contexto | C7: =IFERROR(IF(INDEX('01_Formulario_A00'!$D:$D,MATCH("D01-DOC-DDE-001.IDENTITY.CONTEXTO",'01_Formulario_A00'!$A:$A,0))="","— (a preencher em 01_Formulario_A00)",INDEX('01_Formulario_A00'!$D:$D,MATCH("D01-DOC-DDE-001.IDENTITY.CONTEXTO",'01_Formulario_A00'!$A:$A,0))),"— (a preencher em 01_Formulario_A00)")
A8: D01-DOC-DDE-001.IDENTITY.RAZAO_DE_EXISTENCIA | B8: razao_de_existencia | C8: =IFERROR(IF(INDEX('01_Formulario_A00'!$D:$D,MATCH("D01-DOC-DDE-001.IDENTITY.RAZAO_DE_EXISTENCIA",'01_Formulario_A00'!$A:$A,0))="","— (a preencher em 01_Formulario_A00)",INDEX('01_Formulario_A00'!$D:$D,MATCH("D01-DOC-DDE-001.IDENTITY.RAZAO_DE_EXISTENCIA",'01_Formulario_A00'!$A:$A,0))),"— (a preencher em 01_Formulario_A00)")
A9: D01-DOC-DDE-001.IDENTITY.FASE_ATUAL | B9: fase_atual | C9: =IFERROR(IF(INDEX('01_Formulario_A00'!$D:$D,MATCH("D01-DOC-DDE-001.IDENTITY.FASE_ATUAL",'01_Formulario_A00'!$A:$A,0))="","— (a preencher em 01_Formulario_A00)",INDEX('01_Formulario_A00'!$D:$D,MATCH("D01-DOC-DDE-001.IDENTITY.FASE_ATUAL",'01_Formulario_A00'!$A:$A,0))),"— (a preencher em 01_Formulario_A00)")
A10: D01-DOC-DDE-001.PROBLEM_AND_OPPORTUNITY.PROBLEMA_CENTRAL | B10: problema_central | C10: =IFERROR(IF(INDEX('01_Formulario_A00'!$D:$D,MATCH("D01-DOC-DDE-001.PROBLEM_AND_OPPORTUNITY.PROBLEMA_CENTRAL",'01_Formulario_A00'!$A:$A,0))="","— (a preencher em 01_Formulario_A00)",INDEX('01_Formulario_A00'!$D:$D,MATCH("D01-DOC-DDE-001.PROBLEM_AND_OPPORTUNITY.PROBLEMA_CENTRAL",'01_Formulario_A00'!$A:$A,0))),"— (a preencher em 01_Formulario_A00)")
A11: D01-DOC-DDE-001.PROBLEM_AND_OPPORTUNITY.PROBLEMAS_SECUNDARIOS | B11: problemas_secundarios | C11: =IFERROR(IF(INDEX('01_Formulario_A00'!$D:$D,MATCH("D01-DOC-DDE-001.PROBLEM_AND_OPPORTUNITY.PROBLEMAS_SECUNDARIOS",'01_Formulario_A00'!$A:$A,0))="","— (a preencher em 01_Formulario_A00)",INDEX('01_Formulario_A00'!$D:$D,MATCH("D01-DOC-DDE-001.PROBLEM_AND_OPPORTUNITY.PROBLEMAS_SECUNDARIOS",'01_Formulario_A00'!$A:$A,0))),"— (a preencher em 01_Formulario_A00)")
A12: D01-DOC-DDE-001.PROBLEM_AND_OPPORTUNITY.OPORTUNIDADE | B12: oportunidade | C12: =IFERROR(IF(INDEX('01_Formulario_A00'!$D:$D,MATCH("D01-DOC-DDE-001.PROBLEM_AND_OPPORTUNITY.OPORTUNIDADE",'01_Formulario_A00'!$A:$A,0))="","— (a preencher em 01_Formulario_A00)",INDEX('01_Formulario_A00'!$D:$D,MATCH("D01-DOC-DDE-001.PROBLEM_AND_OPPORTUNITY.OPORTUNIDADE",'01_Formulario_A00'!$A:$A,0))),"— (a preencher em 01_Formulario_A00)")
A13: D01-DOC-DDE-001.PROBLEM_AND_OPPORTUNITY.EVIDENCIAS_DO_PROBLEMA | B13: evidencias_do_problema | C13: =IFERROR(IF(INDEX('01_Formulario_A00'!$D:$D,MATCH("D01-DOC-DDE-001.PROBLEM_AND_OPPORTUNITY.EVIDENCIAS_DO_PROBLEMA",'01_Formulario_A00'!$A:$A,0))="","— (a preencher em 01_Formulario_A00)",INDEX('01_Formulario_A00'!$D:$D,MATCH("D01-DOC-DDE-001.PROBLEM_AND_OPPORTUNITY.EVIDENCIAS_DO_PROBLEMA",'01_Formulario_A00'!$A:$A,0))),"— (a preencher em 01_Formulario_A00)")
A14: D01-DOC-DDE-001.PURPOSE.PROPOSITO | B14: proposito | C14: =IFERROR(IF(INDEX('01_Formulario_A00'!$D:$D,MATCH("D01-DOC-DDE-001.PURPOSE.PROPOSITO",'01_Formulario_A00'!$A:$A,0))="","— (a preencher em 01_Formulario_A00)",INDEX('01_Formulario_A00'!$D:$D,MATCH("D01-DOC-DDE-001.PURPOSE.PROPOSITO",'01_Formulario_A00'!$A:$A,0))),"— (a preencher em 01_Formulario_A00)")
A15: D01-DOC-DDE-001.PURPOSE.MISSAO | B15: missao | C15: =IFERROR(IF(INDEX('01_Formulario_A00'!$D:$D,MATCH("D01-DOC-DDE-001.PURPOSE.MISSAO",'01_Formulario_A00'!$A:$A,0))="","— (a preencher em 01_Formulario_A00)",INDEX('01_Formulario_A00'!$D:$D,MATCH("D01-DOC-DDE-001.PURPOSE.MISSAO",'01_Formulario_A00'!$A:$A,0))),"— (a preencher em 01_Formulario_A00)")
A16: D01-DOC-DDE-001.PURPOSE.VISAO | B16: visao | C16: =IFERROR(IF(INDEX('01_Formulario_A00'!$D:$D,MATCH("D01-DOC-DDE-001.PURPOSE.VISAO",'01_Formulario_A00'!$A:$A,0))="","— (a preencher em 01_Formulario_A00)",INDEX('01_Formulario_A00'!$D:$D,MATCH("D01-DOC-DDE-001.PURPOSE.VISAO",'01_Formulario_A00'!$A:$A,0))),"— (a preencher em 01_Formulario_A00)")
A17: D01-DOC-DDE-001.PURPOSE.PRINCIPIOS | B17: principios | C17: =IFERROR(IF(INDEX('01_Formulario_A00'!$D:$D,MATCH("D01-DOC-DDE-001.PURPOSE.PRINCIPIOS",'01_Formulario_A00'!$A:$A,0))="","— (a preencher em 01_Formulario_A00)",INDEX('01_Formulario_A00'!$D:$D,MATCH("D01-DOC-DDE-001.PURPOSE.PRINCIPIOS",'01_Formulario_A00'!$A:$A,0))),"— (a preencher em 01_Formulario_A00)")
A18: D01-DOC-DDE-001.PURPOSE.VALORES | B18: valores | C18: =IFERROR(IF(INDEX('01_Formulario_A00'!$D:$D,MATCH("D01-DOC-DDE-001.PURPOSE.VALORES",'01_Formulario_A00'!$A:$A,0))="","— (a preencher em 01_Formulario_A00)",INDEX('01_Formulario_A00'!$D:$D,MATCH("D01-DOC-DDE-001.PURPOSE.VALORES",'01_Formulario_A00'!$A:$A,0))),"— (a preencher em 01_Formulario_A00)")
A19: D01-DOC-DDE-001.STRATEGIC_DIRECTION.OBJETIVOS_ESTRATEGICOS | B19: objetivos_estrategicos | C19: =IFERROR(IF(INDEX('01_Formulario_A00'!$D:$D,MATCH("D01-DOC-DDE-001.STRATEGIC_DIRECTION.OBJETIVOS_ESTRATEGICOS",'01_Formulario_A00'!$A:$A,0))="","— (a preencher em 01_Formulario_A00)",INDEX('01_Formulario_A00'!$D:$D,MATCH("D01-DOC-DDE-001.STRATEGIC_DIRECTION.OBJETIVOS_ESTRATEGICOS",'01_Formulario_A00'!$A:$A,0))),"— (a preencher em 01_Formulario_A00)")
A20: D01-DOC-DDE-001.STRATEGIC_DIRECTION.RESULTADOS_ESPERADOS | B20: resultados_esperados | C20: =IFERROR(IF(INDEX('01_Formulario_A00'!$D:$D,MATCH("D01-DOC-DDE-001.STRATEGIC_DIRECTION.RESULTADOS_ESPERADOS",'01_Formulario_A00'!$A:$A,0))="","— (a preencher em 01_Formulario_A00)",INDEX('01_Formulario_A00'!$D:$D,MATCH("D01-DOC-DDE-001.STRATEGIC_DIRECTION.RESULTADOS_ESPERADOS",'01_Formulario_A00'!$A:$A,0))),"— (a preencher em 01_Formulario_A00)")
A21: D01-DOC-DDE-001.STRATEGIC_DIRECTION.PRIORIDADES | B21: prioridades | C21: =IFERROR(IF(INDEX('01_Formulario_A00'!$D:$D,MATCH("D01-DOC-DDE-001.STRATEGIC_DIRECTION.PRIORIDADES",'01_Formulario_A00'!$A:$A,0))="","— (a preencher em 01_Formulario_A00)",INDEX('01_Formulario_A00'!$D:$D,MATCH("D01-DOC-DDE-001.STRATEGIC_DIRECTION.PRIORIDADES",'01_Formulario_A00'!$A:$A,0))),"— (a preencher em 01_Formulario_A00)")
A22: D01-DOC-DDE-001.STRATEGIC_DIRECTION.NAO_OBJETIVOS | B22: nao_objetivos | C22: =IFERROR(IF(INDEX('01_Formulario_A00'!$D:$D,MATCH("D01-DOC-DDE-001.STRATEGIC_DIRECTION.NAO_OBJETIVOS",'01_Formulario_A00'!$A:$A,0))="","— (a preencher em 01_Formulario_A00)",INDEX('01_Formulario_A00'!$D:$D,MATCH("D01-DOC-DDE-001.STRATEGIC_DIRECTION.NAO_OBJETIVOS",'01_Formulario_A00'!$A:$A,0))),"— (a preencher em 01_Formulario_A00)")
A23: D01-DOC-DDE-001.STRATEGIC_DIRECTION.HORIZONTE_TEMPORAL | B23: horizonte_temporal | C23: =IFERROR(IF(INDEX('01_Formulario_A00'!$D:$D,MATCH("D01-DOC-DDE-001.STRATEGIC_DIRECTION.HORIZONTE_TEMPORAL",'01_Formulario_A00'!$A:$A,0))="","— (a preencher em 01_Formulario_A00)",INDEX('01_Formulario_A00'!$D:$D,MATCH("D01-DOC-DDE-001.STRATEGIC_DIRECTION.HORIZONTE_TEMPORAL",'01_Formulario_A00'!$A:$A,0))),"— (a preencher em 01_Formulario_A00)")
A24: D01-DOC-DDE-001.ECOSYSTEM.PRODUTOS | B24: produtos | C24: =IFERROR(IF(INDEX('01_Formulario_A00'!$D:$D,MATCH("D01-DOC-DDE-001.ECOSYSTEM.PRODUTOS",'01_Formulario_A00'!$A:$A,0))="","— (a preencher em 01_Formulario_A00)",INDEX('01_Formulario_A00'!$D:$D,MATCH("D01-DOC-DDE-001.ECOSYSTEM.PRODUTOS",'01_Formulario_A00'!$A:$A,0))),"— (a preencher em 01_Formulario_A00)")
A25: D01-DOC-DDE-001.ECOSYSTEM.SERVICOS | B25: servicos | C25: =IFERROR(IF(INDEX('01_Formulario_A00'!$D:$D,MATCH("D01-DOC-DDE-001.ECOSYSTEM.SERVICOS",'01_Formulario_A00'!$A:$A,0))="","— (a preencher em 01_Formulario_A00)",INDEX('01_Formulario_A00'!$D:$D,MATCH("D01-DOC-DDE-001.ECOSYSTEM.SERVICOS",'01_Formulario_A00'!$A:$A,0))),"— (a preencher em 01_Formulario_A00)")
A26: D01-DOC-DDE-001.ECOSYSTEM.MARCAS | B26: marcas | C26: =IFERROR(IF(INDEX('01_Formulario_A00'!$D:$D,MATCH("D01-DOC-DDE-001.ECOSYSTEM.MARCAS",'01_Formulario_A00'!$A:$A,0))="","— (a preencher em 01_Formulario_A00)",INDEX('01_Formulario_A00'!$D:$D,MATCH("D01-DOC-DDE-001.ECOSYSTEM.MARCAS",'01_Formulario_A00'!$A:$A,0))),"— (a preencher em 01_Formulario_A00)")
A27: D01-DOC-DDE-001.ECOSYSTEM.AGENTES | B27: agentes | C27: =IFERROR(IF(INDEX('01_Formulario_A00'!$D:$D,MATCH("D01-DOC-DDE-001.ECOSYSTEM.AGENTES",'01_Formulario_A00'!$A:$A,0))="","— (a preencher em 01_Formulario_A00)",INDEX('01_Formulario_A00'!$D:$D,MATCH("D01-DOC-DDE-001.ECOSYSTEM.AGENTES",'01_Formulario_A00'!$A:$A,0))),"— (a preencher em 01_Formulario_A00)")
A28: D01-DOC-DDE-001.ECOSYSTEM.PLATAFORMAS | B28: plataformas | C28: =IFERROR(IF(INDEX('01_Formulario_A00'!$D:$D,MATCH("D01-DOC-DDE-001.ECOSYSTEM.PLATAFORMAS",'01_Formulario_A00'!$A:$A,0))="","— (a preencher em 01_Formulario_A00)",INDEX('01_Formulario_A00'!$D:$D,MATCH("D01-DOC-DDE-001.ECOSYSTEM.PLATAFORMAS",'01_Formulario_A00'!$A:$A,0))),"— (a preencher em 01_Formulario_A00)")
A29: D01-DOC-DDE-001.ECOSYSTEM.UNIDADES_DE_NEGOCIO | B29: unidades_de_negocio | C29: =IFERROR(IF(INDEX('01_Formulario_A00'!$D:$D,MATCH("D01-DOC-DDE-001.ECOSYSTEM.UNIDADES_DE_NEGOCIO",'01_Formulario_A00'!$A:$A,0))="","— (a preencher em 01_Formulario_A00)",INDEX('01_Formulario_A00'!$D:$D,MATCH("D01-DOC-DDE-001.ECOSYSTEM.UNIDADES_DE_NEGOCIO",'01_Formulario_A00'!$A:$A,0))),"— (a preencher em 01_Formulario_A00)")
A30: D01-DOC-DDE-001.GOVERNANCE.MODELO_DE_GOVERNANCA | B30: modelo_de_governanca | C30: =IFERROR(IF(INDEX('01_Formulario_A00'!$D:$D,MATCH("D01-DOC-DDE-001.GOVERNANCE.MODELO_DE_GOVERNANCA",'01_Formulario_A00'!$A:$A,0))="","— (a preencher em 01_Formulario_A00)",INDEX('01_Formulario_A00'!$D:$D,MATCH("D01-DOC-DDE-001.GOVERNANCE.MODELO_DE_GOVERNANCA",'01_Formulario_A00'!$A:$A,0))),"— (a preencher em 01_Formulario_A00)")
A31: D01-DOC-DDE-001.GOVERNANCE.PAPEIS_DECISORIOS | B31: papeis_decisorios | C31: =IFERROR(IF(INDEX('01_Formulario_A00'!$D:$D,MATCH("D01-DOC-DDE-001.GOVERNANCE.PAPEIS_DECISORIOS",'01_Formulario_A00'!$A:$A,0))="","— (a preencher em 01_Formulario_A00)",INDEX('01_Formulario_A00'!$D:$D,MATCH("D01-DOC-DDE-001.GOVERNANCE.PAPEIS_DECISORIOS",'01_Formulario_A00'!$A:$A,0))),"— (a preencher em 01_Formulario_A00)")
A32: D01-DOC-DDE-001.GOVERNANCE.DIREITOS_DE_DECISAO | B32: direitos_de_decisao | C32: =IFERROR(IF(INDEX('01_Formulario_A00'!$D:$D,MATCH("D01-DOC-DDE-001.GOVERNANCE.DIREITOS_DE_DECISAO",'01_Formulario_A00'!$A:$A,0))="","— (a preencher em 01_Formulario_A00)",INDEX('01_Formulario_A00'!$D:$D,MATCH("D01-DOC-DDE-001.GOVERNANCE.DIREITOS_DE_DECISAO",'01_Formulario_A00'!$A:$A,0))),"— (a preencher em 01_Formulario_A00)")
A33: D01-DOC-DDE-001.GOVERNANCE.GATES | B33: gates | C33: =IFERROR(IF(INDEX('01_Formulario_A00'!$D:$D,MATCH("D01-DOC-DDE-001.GOVERNANCE.GATES",'01_Formulario_A00'!$A:$A,0))="","— (a preencher em 01_Formulario_A00)",INDEX('01_Formulario_A00'!$D:$D,MATCH("D01-DOC-DDE-001.GOVERNANCE.GATES",'01_Formulario_A00'!$A:$A,0))),"— (a preencher em 01_Formulario_A00)")
A34: D01-DOC-DDE-001.GOVERNANCE.MECANISMOS_DE_CONTROLE | B34: mecanismos_de_controle | C34: =IFERROR(IF(INDEX('01_Formulario_A00'!$D:$D,MATCH("D01-DOC-DDE-001.GOVERNANCE.MECANISMOS_DE_CONTROLE",'01_Formulario_A00'!$A:$A,0))="","— (a preencher em 01_Formulario_A00)",INDEX('01_Formulario_A00'!$D:$D,MATCH("D01-DOC-DDE-001.GOVERNANCE.MECANISMOS_DE_CONTROLE",'01_Formulario_A00'!$A:$A,0))),"— (a preencher em 01_Formulario_A00)")
A35: D01-DOC-DDE-001.STAKEHOLDERS.STAKEHOLDERS | B35: stakeholders | C35: =IFERROR(IF(INDEX('01_Formulario_A00'!$D:$D,MATCH("D01-DOC-DDE-001.STAKEHOLDERS.STAKEHOLDERS",'01_Formulario_A00'!$A:$A,0))="","— (a preencher em 01_Formulario_A00)",INDEX('01_Formulario_A00'!$D:$D,MATCH("D01-DOC-DDE-001.STAKEHOLDERS.STAKEHOLDERS",'01_Formulario_A00'!$A:$A,0))),"— (a preencher em 01_Formulario_A00)")
A36: D01-DOC-DDE-001.STAKEHOLDERS.INTERESSE | B36: interesse | C36: =IFERROR(IF(INDEX('01_Formulario_A00'!$D:$D,MATCH("D01-DOC-DDE-001.STAKEHOLDERS.INTERESSE",'01_Formulario_A00'!$A:$A,0))="","— (a preencher em 01_Formulario_A00)",INDEX('01_Formulario_A00'!$D:$D,MATCH("D01-DOC-DDE-001.STAKEHOLDERS.INTERESSE",'01_Formulario_A00'!$A:$A,0))),"— (a preencher em 01_Formulario_A00)")
A37: D01-DOC-DDE-001.STAKEHOLDERS.INFLUENCIA | B37: influencia | C37: =IFERROR(IF(INDEX('01_Formulario_A00'!$D:$D,MATCH("D01-DOC-DDE-001.STAKEHOLDERS.INFLUENCIA",'01_Formulario_A00'!$A:$A,0))="","— (a preencher em 01_Formulario_A00)",INDEX('01_Formulario_A00'!$D:$D,MATCH("D01-DOC-DDE-001.STAKEHOLDERS.INFLUENCIA",'01_Formulario_A00'!$A:$A,0))),"— (a preencher em 01_Formulario_A00)")
A38: D01-DOC-DDE-001.STAKEHOLDERS.RELACIONAMENTO | B38: relacionamento | C38: =IFERROR(IF(INDEX('01_Formulario_A00'!$D:$D,MATCH("D01-DOC-DDE-001.STAKEHOLDERS.RELACIONAMENTO",'01_Formulario_A00'!$A:$A,0))="","— (a preencher em 01_Formulario_A00)",INDEX('01_Formulario_A00'!$D:$D,MATCH("D01-DOC-DDE-001.STAKEHOLDERS.RELACIONAMENTO",'01_Formulario_A00'!$A:$A,0))),"— (a preencher em 01_Formulario_A00)")
A39: D01-DOC-DDE-001.STRATEGIC_DEPENDENCIES.DEPENDENCIAS | B39: dependencias | C39: =IFERROR(IF(INDEX('01_Formulario_A00'!$D:$D,MATCH("D01-DOC-DDE-001.STRATEGIC_DEPENDENCIES.DEPENDENCIAS",'01_Formulario_A00'!$A:$A,0))="","— (a preencher em 01_Formulario_A00)",INDEX('01_Formulario_A00'!$D:$D,MATCH("D01-DOC-DDE-001.STRATEGIC_DEPENDENCIES.DEPENDENCIAS",'01_Formulario_A00'!$A:$A,0))),"— (a preencher em 01_Formulario_A00)")
A40: D01-DOC-DDE-001.STRATEGIC_DEPENDENCIES.RESTRICOES | B40: restricoes | C40: =IFERROR(IF(INDEX('01_Formulario_A00'!$D:$D,MATCH("D01-DOC-DDE-001.STRATEGIC_DEPENDENCIES.RESTRICOES",'01_Formulario_A00'!$A:$A,0))="","— (a preencher em 01_Formulario_A00)",INDEX('01_Formulario_A00'!$D:$D,MATCH("D01-DOC-DDE-001.STRATEGIC_DEPENDENCIES.RESTRICOES",'01_Formulario_A00'!$A:$A,0))),"— (a preencher em 01_Formulario_A00)")
A41: D01-DOC-DDE-001.STRATEGIC_DEPENDENCIES.PREMISSAS | B41: premissas | C41: =IFERROR(IF(INDEX('01_Formulario_A00'!$D:$D,MATCH("D01-DOC-DDE-001.STRATEGIC_DEPENDENCIES.PREMISSAS",'01_Formulario_A00'!$A:$A,0))="","— (a preencher em 01_Formulario_A00)",INDEX('01_Formulario_A00'!$D:$D,MATCH("D01-DOC-DDE-001.STRATEGIC_DEPENDENCIES.PREMISSAS",'01_Formulario_A00'!$A:$A,0))),"— (a preencher em 01_Formulario_A00)")
A42: D01-DOC-DDE-001.RISKS.RISCOS_ESTRATEGICOS | B42: riscos_estrategicos | C42: =IFERROR(IF(INDEX('01_Formulario_A00'!$D:$D,MATCH("D01-DOC-DDE-001.RISKS.RISCOS_ESTRATEGICOS",'01_Formulario_A00'!$A:$A,0))="","— (a preencher em 01_Formulario_A00)",INDEX('01_Formulario_A00'!$D:$D,MATCH("D01-DOC-DDE-001.RISKS.RISCOS_ESTRATEGICOS",'01_Formulario_A00'!$A:$A,0))),"— (a preencher em 01_Formulario_A00)")
...

Sheet 04_Visao_Portfolio
A1: portfolio_id | B1: name | C1: type | D1: status | E1: owner
A2: S0 | B2: Executar programa governança e operações. | C2: PROGRAM_OPS | D2: ACTIVE | E2: A_DEFINIR
A3: M0 | B3: Executar Institucional | C3: PRODUCT_INITIATIVE | D3: ACTIVE | E3: A_DEFINIR
A4: M1 | B4: Executar App | C4: PRODUCT_INITIATIVE | D4: ACTIVE | E4: A_DEFINIR
A5: M2 | B5: Executar Blog | C5: PRODUCT_INITIATIVE | D5: ACTIVE | E5: A_DEFINIR
A6: M2.1 | B6: Risco cognitivo Blog | C6: PRODUCT_INITIATIVE | D6: ACTIVE | E6: A_DEFINIR
A7: M3 | B7: Executar Oficina | C7: PRODUCT_INITIATIVE | D7: ACTIVE | E7: A_DEFINIR
A8: M4 | B8: Executar Mapa Cognitivo | C8: PRODUCT_INITIATIVE | D8: ACTIVE | E8: A_DEFINIR
A9: M5 | B9: Executar Agente Copiloto | C9: PRODUCT_INITIATIVE | D9: ACTIVE | E9: A_DEFINIR
A10: M6 | B10: Executar Agente Maestro | C10: PRODUCT_INITIATIVE | D10: ACTIVE | E10: A_DEFINIR
A11: M7 | B11: Executar Agente Vera | C11: PRODUCT_INITIATIVE | D11: ACTIVE | E11: A_DEFINIR
A12: M7.1 | B12: Executar emprego e portfólio | C12: PRODUCT_INITIATIVE | D12: ACTIVE | E12: A_DEFINIR
... A21: M16 | B21: Executar lead business creator strategy launch | C21: PRODUCT_INITIATIVE | D21: ACTIVE | E21: A_DEFINIR

Sheet 05_Visao_Artefatos
B2: Visão Artefatos — espelho narrativo (não editar; ver 01_Formulario_*)
A4: D01-DOC-DDE-001 — Documento de Direção Empresarial [PRE_PREENCHIDO/PENDENTE]
A5: D01-DOC-DDE-001.IDENTITY.NOME_DO_ECOSSISTEMA | B5: nome_do_ecossistema | C5: =IFERROR(IF(INDEX('01_Formulario_A00'!$D:$D,MATCH("D01-DOC-DDE-001.IDENTITY.NOME_DO_ECOSSISTEMA",'01_Formulario_A00'!$A:$A,0))="","— (a preencher em 01_Formulario_A00)",INDEX('01_Formulario_A00'!$D:$D,MATCH("D01-DOC-DDE-001.IDENTITY.NOME_DO_ECOSSISTEMA",'01_Formulario_A00'!$A:$A,0))),"— (a preencher em 01_Formulario_A00)")
A6: D01-DOC-DDE-001.IDENTITY.DESCRICAO_EXECUTIVA | B6: descricao_executiva | C6: =IFERROR(IF(INDEX('01_Formulario_A00'!$D:$D,MATCH("D01-DOC-DDE-001.IDENTITY.DESCRICAO_EXECUTIVA",'01_Formulario_A00'!$A:$A,0))="","— (a preencher em 01_Formulario_A00)",INDEX('01_Formulario_A00'!$D:$D,MATCH("D01-DOC-DDE-001.IDENTITY.DESCRICAO_EXECUTIVA",'01_Formulario_A00'!$A:$A,0))),"— (a preencher em 01_Formulario_A00)")
A7: D01-DOC-DDE-001.IDENTITY.CONTEXTO | B7: contexto | C7: =IFERROR(IF(INDEX('01_Formulario_A00'!$D:$D,MATCH("D01-DOC-DDE-001.IDENTITY.CONTEXTO",'01_Formulario_A00'!$A:$A,0))="","— (a preencher em 01_Formulario_A00)",INDEX('01_Formulario_A00'!$D:$D,MATCH("D01-DOC-DDE-001.IDENTITY.CONTEXTO",'01_Formulario_A00'!$A:$A,0))),"— (a preencher em 01_Formulario_A00)")
A8: D01-DOC-DDE-001.IDENTITY.RAZAO_DE_EXISTENCIA | B8: razao_de_existencia | C8: =IFERROR(IF(INDEX('01_Formulario_A00'!$D:$D,MATCH("D01-DOC-DDE-001.IDENTITY.RAZAO_DE_EXISTENCIA",'01_Formulario_A00'!$A:$A,0))="","— (a preencher em 01_Formulario_A00)",INDEX('01_Formulario_A00'!$D:$D,MATCH("D01-DOC-DDE-001.IDENTITY.RAZAO_DE_EXISTENCIA",'01_Formulario_A00'!$A:$A,0))),"— (a preencher em 01_Formulario_A00)")
A9: D01-DOC-DDE-001.IDENTITY.FASE_ATUAL | B9: fase_atual | C9: =IFERROR(IF(INDEX('01_Formulario_A00'!$D:$D,MATCH("D01-DOC-DDE-001.IDENTITY.FASE_ATUAL",'01_Formulario_A00'!$A:$A,0))="","— (a preencher em 01_Formulario_A00)",INDEX('01_Formulario_A00'!$D:$D,MATCH("D01-DOC-DDE-001.IDENTITY.FASE_ATUAL",'01_Formulario_A00'!$A:$A,0))),"— (a preencher em 01_Formulario_A00)")
A10: D01-DOC-DDE-001.PROBLEM_AND_OPPORTUNITY.PROBLEMA_CENTRAL | B10: problema_central | C10: =IFERROR(IF(INDEX('01_Formulario_A00'!$D:$D,MATCH("D01-DOC-DDE-001.PROBLEM_AND_OPPORTUNITY.PROBLEMA_CENTRAL",'01_Formulario_A00'!$A:$A,0))="","— (a preencher em 01_Formulario_A00)",INDEX('01_Formulario_A00'!$D:$D,MATCH("D01-DOC-DDE-001.PROBLEM_AND_OPPORTUNITY.PROBLEMA_CENTRAL",'01_Formulario_A00'!$A:$A,0))),"— (a preencher em 01_Formulario_A00)")
A11: D01-DOC-DDE-001.PROBLEM_AND_OPPORTUNITY.PROBLEMAS_SECUNDARIOS | B11: problemas_secundarios | C11: =IFERROR(IF(INDEX('01_Formulario_A00'!$D:$D,MATCH("D01-DOC-DDE-001.PROBLEM_AND_OPPORTUNITY.PROBLEMAS_SECUNDARIOS",'01_Formulario_A00'!$A:$A,0))="","— (a preencher em 01_Formulario_A00)",INDEX('01_Formulario_A00'!$D:$D,MATCH("D01-DOC-DDE-001.PROBLEM_AND_OPPORTUNITY.PROBLEMAS_SECUNDARIOS",'01_Formulario_A00'!$A:$A,0))),"— (a preencher em 01_Formulario_A00)")
